<?xml version="1.0" encoding="UTF-8"?>
<robot name='smartcar'>
	<link name='base_link'>
		<visual>
			<geometry>
				<box size="0.25 0.16 0.05"/>
			</geometry>
			<origin rpy="0 0 1.57075" xyz="0 0 0"/>
			<material name="blue">
				<color rgba="0 0.8 0 1"/>
			</material>
		</visual>
	</link>
	<link name="right_wheel">
		<visual>
			<geometry>
				<cylinder length="0.02" radius="0.025"/>
			</geometry>
			<material name="black">
				<color rgba="0 0 0 1"/>
			</material>
		</visual>
	</link>
	<joint name="right_wheel_joint" type="continuous">
		<axis xyz="0 0 1"/>
		<parent link="base_link"/>
		<child link="right_wheel"/>
		<origin rpy="0 1.57075 0" xyz="0.08 0.1 -0.03"/>
		<limit effort="100" velocity="100"/>
		<joint_properties damping="0.0" friction="0.0"/>
	</joint>
	<link name="left_wheel">
		<visual>
			<geometry>
				<cylinder length="0.02" radius="0.025"/>
			</geometry>
			<material name="black">
				<color rgba="0 0 0 1"/>
			</material>
		</visual>
	</link>
	<joint name="left_wheel_joint" type="continuous">
		<axis xyz="0 0 1"/>
		<parent link="base_link"/>
		<child link="left_wheel"/>
		<origin rpy="0 1.57075 0" xyz="0.08 0.1 -0.03"/>
		<limit effort="100" velocity="100"/>
		<joint_properties damping="0.0" friction="0.0"/>
	</joint>
	<link name="laser_scanner">
		<visual>
			<geometry>
				<cylinder length="0.05" radius="0.05"/>
			</geometry>
			<material name="green">
				<color rgba="1 1 1 1"/>
			</material>
		</visual>
	</link>
	<joint name="to_base_link" type="fixed">
		<parent link="base_link"/>
		<child link="laser_scanner"/>
		<origin xyz="0 0.08 0.025"/>
	</joint>
</robot>